Workbook
Name CenaSE: INDIRECT([2]OUTPUT_SIP!$AH$13)
Name EDV: INDIRECT([2]OUTPUT_SIP!$AH$8)
Name inflacija: [2]parametri!$B$5
Name LastnaRaba: INDIRECT([2]OUTPUT_SIP!$AH$10)
Name PowerSE: INDIRECT([2]OUTPUT_SIP!$AH$7)
Name ProizvodnjaSE: INDIRECT([2]OUTPUT_SIP!$AH$9)
Name Samooskrbnost: INDIRECT([2]OUTPUT_SIP!$AH$12)
Name Viski: INDIRECT([2]OUTPUT_SIP!$AH$11)

Sheet Življenska doba JEK2
A1: Življenska doba [let] | B1: Delež pojavljanja [%]
A2: 40 | B2: 0
A3: 60 | B3: 0.2
A4: 80 | B4: 0.6
A5: 100 | B5: 0.2

Sheet Inštalirana kapaciteta
A1: Inštalirana kapaciteta [MW] | B1: 1000
B2: 1250
B3: 1650

Sheet Capacity factor
A1: Trikotna distribucija
A2: Min | B2: 0.85
A3: Modus | B3: 0.91
A4: Max | B4: 0.95
A5: Povperčen CF | B5: =AVERAGE(B2:B4) -> 0.90333333
L7: Chooz B-2 | M7: Generation II (Upgraded in the 1980s,1990s and 2000s after Chernobyl) | O7: PWR (N4 REP 1450) | P7: 1500 | Q7: 69.6 | R7: =IF(Q7>75,Q7,"")
L8: Chooz B-1 | M8: Generation II (Upgraded in the 1980s,1990s and 2000s after Chernobyl) | O8: PWR (N4 REP 1450) | P8: 1500 | Q8: 71.6 | R8: =IF(Q8>75,Q8,"")
L9: Golfech-2 | M9: Generation II (Upgraded in the 1980s,1990s and 2000s after Chernobyl) | O9: PWR (P4 REP 1300) | P9: 1310 | Q9: 74.4 | R9: =IF(Q9>75,Q9,"")
L10: Penly-2 | M10: Generation II (Upgraded in the 1980s,1990s and 2000s after Chernobyl) | O10: PWR (P4 REP 1300) | P10: 1330 | Q10: 75.1 | R10: =IF(Q10>75,Q10,"") -> 75.1
L11: Cattenom-4 | M11: Generation II (Upgraded in the 1980s,1990s and 2000s after Chernobyl) | O11: PWR (P4 REP 1300) | P11: 1300 | Q11: 75.5 | R11: =IF(Q11>75,Q11,"") -> 75.5
L12: Cattenom-3 | M12: Generation II (Upgraded in the 1980s,1990s and 2000s after Chernobyl) | O12: PWR (P4 REP 1300) | P12: 1300 | Q12: 71.3 | R12: =IF(Q12>75,Q12,"")
L13: Golfech-1 | M13: Generation II (Upgraded in the 1980s,1990s and 2000s after Chernobyl) | O13: PWR (P4 REP 1300) | P13: 1310 | Q13: 72.5 | R13: =IF(Q13>75,Q13,"")
L14: Penly-2 | M14: Generation II (Upgraded in the 1980s,1990s and 2000s after Chernobyl) | O14: PWR (P4 REP 1300) | P14: 1330 | Q14: 72.3 | R14: =IF(Q14>75,Q14,"")
L15: Nogent-2 | M15: Generation II (Upgraded in the 1980s,1990s and 2000s after Chernobyl) | O15: PWR (P4 REP 1300) | P15: 1310 | Q15: 74.2 | R15: =IF(Q15>75,Q15,"")
L16: Belleville-2 | M16: Generation II (Upgraded in the 1980s,1990s and 2000s after Chernobyl) | O16: PWR (P4 REP 1300) | P16: 1310 | Q16: 71.6 | R16: =IF(Q16>75,Q16,"")
L17: Chinon B-4 | M17: Generation II (Upgraded in the 1980s,1990s and 2000s after Chernobyl) | O17: PWR (CP2) | P17: 905 | Q17: 74.6 | R17: =IF(Q17>75,Q17,"")
L18: Nogent-1 | M18: Generation II (Upgraded in the 1980s,1990s and 2000s after Chernobyl) | O18: PWR (P4 REP 1300) | P18: 1310 | Q18: 72.4 | R18: =IF(Q18>75,Q18,"")
... L20: Cattenom-2 | M20: Generation II (Upgraded in the 1980s,1990s and 2000s after Chernobyl) | O20: PWR (P4 REP 1300) | P20: 1300 | Q20: 71.8 | R20: =IF(Q20>75,Q20,"")
L21: UK | R21: =IF(Q21>75,Q21,"")
L22: Bradwell 2 | M22: Generation III+ | O22: Hualong one | P22: 1150 | R22: =IF(Q22>75,Q22,"")
L23: Bradwell 1 | M23: Generation III+ | O23: Hualong one | P23: 1150 | R23: =IF(Q23>75,Q23,"")
L24: Sizewell C2 | M24: Generation III+ | O24: PWR (EPR-1600) | P24: 1670 | R24: =IF(Q24>75,Q24,"")
L25: Sizewell C1 | M25: Generation III+ | O25: PWR (EPR-1600) | P25: 1670 | R25: =IF(Q25>75,Q25,"")
L26: Hinkley Point C1 | M26: Generation III+ | O26: PWR (EPR-1600) | P26: 1630 | R26: =IF(Q26>75,Q26,"")
L27: Hinkley Point C2 | M27: Generation III+ | O27: PWR (EPR-1600) | P27: 1630 | R27: =IF(Q27>75,Q27,"")
L28: Sizewell B | M28: Generation II (Upgraded in the 1980s,1990s and 2000s after Chernobyl) | O28: PWR (SNUPPS) | P28: 1198 | Q28: 83.1 | R28: =IF(Q28>75,Q28,"") -> 83.1
L29: Torness-2 | M29: Generation II (Upgraded in the 1980s,1990s and 2000s after Chernobyl) | O29: GCR (AGR) | P29: 605 | Q29: 76.5 | R29: =IF(Q29>75,Q29,"") -> 76.5
L30: Heysham B-2 | M30: Generation II (Upgraded in the 1980s,1990s and 2000s after Chernobyl) | O30: GCR (AGR) | P30: 620 | Q30: 76.8 | R30: =IF(Q30>75,Q30,"") -> 76.8
L31: Heysham B-1 | M31: Generation II (Upgraded in the 1980s,1990s and 2000s after Chernobyl) | O31: GCR (AGR) | P31: 620 | Q31: 80.8 | R31: =IF(Q31>75,Q31,"") -> 80.8
L32: Torness-2 | M32: Generation II (Upgraded in the 1980s,1990s and 2000s after Chernobyl) | O32: GCR (AGR) | P32: 595 | Q32: 81.1 | R32: =IF(Q32>75,Q32,"") -> 81.1
L33: US | R33: =IF(Q33>75,Q33,"")
L34: Turkey point 7 | M34: Generation III+ | O34: PWR (AP-1000) | P34: 1538 | R34: =IF(Q34>75,Q34,"")
L35: Turkey point 6 | M35: Generation III+ | O35: PWR (AP-1000) | R35: =IF(Q35>75,Q35,"")
L36: Fermi 3 | M36: Generation III+ | O36: ESBWR | R36: =IF(Q36>75,Q36,"")
L37: North Anna | M37: Generation III+ | O37: ESBWR | R37: =IF(Q37>75,Q37,"")
L38: Clinch River | M38: Generation III+ | O38: / | R38: =IF(Q38>75,Q38,"")
L39: Bellefonte 2 | M39: Generation III+ | O39: PWR (B&W) | R39: =IF(Q39>75,Q39,"")
L40: Bellefonte 1 | M40: Generation III+ | O40: PWR (B&W) | R40: =IF(Q40>75,Q40,"")
L41: Salem 3 | M41: Generation III+ | O41: / | R41: =IF(Q41>75,Q41,"")
L42: Vogtle-4 | M42: Generation III+ | O42: PWR (AP1000) | P42: 1117 | R42: =IF(Q42>75,Q42,"")
...

Sheet CAPEX
A1: Cost escalation rate during preconstruction and construction period (r) [%] | B1: 0.019551524
A2: Depreciacijska doba [let] | B2: 40
A3: Podaljšanje gradnje zaradi priprave dokumentacije [let] | B3: 4.5 | C3: Min construction period
A4: Podaljšanje gradnje zaradi prestavitve RTP, 400 kV stikališča, 3 400 kV daljnovodov in 7 100 kV povezav ob predpostavki sklenjenega sporazuma med investitorjem in ELES [let] | B4: 0 | C4: {=MIN(IF(ISNA(D9:D89), "",D9:D89))} -> 8.5
A5: Povečanje OCC initial za seizmično nadgradnjo lokacije + ostale postavke [EUR2024/kW] | B5: =495.63+200*0.5 -> 595.63 | C5: Max construction period
A6: Minimalna vrednost OCC initial | B6: {=MIN(IF(ISNA(G9:G89), "",G9:G89))} -> 3613.1181 | C6: {=MAX(IF(ISNA(D9:D89), "",D9:D89))} -> 29.5
A7: Maksimalna vrednost OCC initial | B7: {=MAX(IF(ISNA(G9:G89), "",G9:G89))} -> 11991.264
A8: JEDRSKA ELEKTRARNA | B8: Država | C8: Čas gradnje [let] | D8: Čas gradnje povečan za planiranje in prestavitev elektroenergetske infrastrukture [let] | E8: OCC initial [EUR2024/kW] | F8: OCC initial, povečan za seizmiko [EUR2024/kW] | G8: OCC initial, povečan za seizmiko, ostale jek2-povezane postavke in delno prilagoje za Južno Korejo [EUR2024/kW] | H8: Capacity factor - proba, ne uporabljaš
A9: Olkiluoto 3 | B9: FI | C9: 18 | D9: =IF(ISNUMBER(C9+SUM($B$3:$B$4)),C9+SUM($B$3:$B$4),NA()) -> 22.5 | E9: 4466.6043 | F9: =IF(ISNUMBER(E9+$B$5),E9+$B$5,NA()) -> 5062.2343 | G9: =F9 -> 5062.2343 | H9: =IFERROR(VLOOKUP(A9,'Capacity factor'!$L$7:$R$129,6,FALSE),"")
A10: Flamanville 3 | B10: FR | C10: 18 | D10: =IF(ISNUMBER(C10+SUM($B$3:$B$4)),C10+SUM($B$3:$B$4),NA()) -> 22.5 | E10: 3030.7655 | F10: =IF(ISNUMBER(E10+$B$5),E10+$B$5,NA()) -> 3626.3955 | G10: =F10 -> 3626.3955 | H10: =IFERROR(VLOOKUP(A10,'Capacity factor'!$L$7:$R$129,6,FALSE),"") | I10: Koliko vrednosti upoštevano v distribucijo | J10: =COUNT(G9:G89) -> 46
A11: Vogtle-4 | B11: US | C11: 10 | D11: =IF(ISNUMBER(C11+SUM($B$3:$B$4)),C11+SUM($B$3:$B$4),NA()) -> 14.5 | E11: 6352.62 | F11: =IF(ISNUMBER(E11+$B$5),E11+$B$5,NA()) -> 6948.25 | G11: =F11 -> 6948.25 | H11: =IFERROR(VLOOKUP(A11,'Capacity factor'!$L$7:$R$129,6,FALSE),"") -> 0 | I11: Koliko vrednosti upoštevano v distribucijo | J11: =COUNT(D9:D89) -> 23
A12: Vogtle-3 | B12: US | C12: 10 | D12: =IF(ISNUMBER(C12+SUM($B$3:$B$4)),C12+SUM($B$3:$B$4),NA()) -> 14.5 | E12: 6352.62 | F12: =IF(ISNUMBER(E12+$B$5),E12+$B$5,NA()) -> 6948.25 | G12: =F12 -> 6948.25 | H12: =IFERROR(VLOOKUP(A12,'Capacity factor'!$L$7:$R$129,6,FALSE),"") -> 99.3
A13: Shin Hanul 2 | B13: KOR | C13: 11 | D13: #N/A | E13: 3086.0791 | F13: =IF(ISNUMBER(E13+$B$5),E13+$B$5,NA()) -> 3681.7091 | G13: #N/A | H13: =IFERROR(VLOOKUP(A13,'Capacity factor'!$L$7:$R$129,6,FALSE),"") -> 0
A14: Shin Hanul 1 | B14: KOR | C14: 10 | D14: #N/A | E14: 3161.6379 | F14: =IF(ISNUMBER(E14+$B$5),E14+$B$5,NA()) -> 3757.2679 | G14: #N/A | H14: =IFERROR(VLOOKUP(A14,'Capacity factor'!$L$7:$R$129,6,FALSE),"") -> 99.5 | I14: Min
A15: Saeul 2 | B15: KOR | C15: 10 | D15: =IF(ISNUMBER(C15+SUM($B$3:$B$4)),C15+SUM($B$3:$B$4),NA()) -> 14.5 | E15: #DIV/0! | F15: =IF(ISNUMBER(E15+$B$5),E15+$B$5,NA()) -> #N/A | G15: =F15 -> #N/A | H15: =IFERROR(VLOOKUP(A15,'Capacity factor'!$L$7:$R$129,6,FALSE),"") -> 83.9 | I15: Max
A16: Saeul 1 | B16: KOR | C16: 8 | D16: =IF(ISNUMBER(C16+SUM($B$3:$B$4)),C16+SUM($B$3:$B$4),NA()) -> 12.5 | E16: #DIV/0! | F16: =IF(ISNUMBER(E16+$B$5),E16+$B$5,NA()) -> #N/A | G16: =F16 -> #N/A | H16: =IFERROR(VLOOKUP(A16,'Capacity factor'!$L$7:$R$129,6,FALSE),"") -> 79.2
A17: Shin Wolsong-2 | B17: KOR | C17: 7 | D17: #N/A | E17: 2698.7702 | F17: =IF(ISNUMBER(E17+$B$5),E17+$B$5,NA()) -> 3294.4002 | G17: #N/A | H17: =IFERROR(VLOOKUP(A17,'Capacity factor'!$L$7:$R$129,6,FALSE),"") -> 85.4
A18: Shin Kori-5/6 | B18: KOR | C18: 7 | D18: =IF(ISNUMBER(C18+SUM($B$3:$B$4)),C18+SUM($B$3:$B$4),NA()) -> 11.5 | E18: 4631.2532 | F18: =IF(ISNUMBER(E18+$B$5),E18+$B$5,NA()) -> 5226.8832 | G18: =F18 -> 5226.8832 | H18: =IFERROR(VLOOKUP(A18,'Capacity factor'!$L$7:$R$129,6,FALSE),"")
A19: Shin Kori-3/4 | B19: KOR | C19: 11 | D19: =IF(ISNUMBER(C19+SUM($B$3:$B$4)),C19+SUM($B$3:$B$4),NA()) -> 15.5 | E19: 3830.1851 | F19: =IF(ISNUMBER(E19+$B$5),E19+$B$5,NA()) -> 4425.8151 | G19: =F19 -> 4425.8151 | H19: =IFERROR(VLOOKUP(A19,'Capacity factor'!$L$7:$R$129,6,FALSE),"")
A20: Shin Kori-2 | B20: KOR | C20: 5 | D20: =IF(ISNUMBER(C20+SUM($B$3:$B$4)),C20+SUM($B$3:$B$4),NA()) -> 9.5 | E20: #DIV/0! | F20: =IF(ISNUMBER(E20+$B$5),E20+$B$5,NA()) -> #N/A | G20: =F20 -> #N/A | H20: =IFERROR(VLOOKUP(A20,'Capacity factor'!$L$7:$R$129,6,FALSE),"") -> 83.7
A21: Shin Wolsong-1 | B21: KOR | C21: 5 | D21: #N/A | E21: 2692.8096 | F21: =IF(ISNUMBER(E21+$B$5),E21+$B$5,NA()) -> 3288.4396 | G21: #N/A | H21: =IFERROR(VLOOKUP(A21,'Capacity factor'!$L$7:$R$129,6,FALSE),"") -> 82.9
A22: Shin Kori 1 | B22: KOR | C22: 5 | D22: =IF(ISNUMBER(C22+SUM($B$3:$B$4)),C22+SUM($B$3:$B$4),NA()) -> 9.5 | E22: #DIV/0! | F22: =IF(ISNUMBER(E22+$B$5),E22+$B$5,NA()) -> #N/A | G22: =F22 -> #N/A | H22: =IFERROR(VLOOKUP(A22,'Capacity factor'!$L$7:$R$129,6,FALSE),"") -> 76.1
A23: Hanul-6 | B23: KOR | C23: 5 | D23: =IF(ISNUMBER(C23+SUM($B$3:$B$4)),C23+SUM($B$3:$B$4),NA()) -> 9.5 | E23: #DIV/0! | F23: =IF(ISNUMBER(E23+$B$5),E23+$B$5,NA()) -> #N/A | G23: =F23 -> #N/A | H23: =IFERROR(VLOOKUP(A23,'Capacity factor'!$L$7:$R$129,6,FALSE),"") -> 88.6
A24: Hanul-5 | B24: KOR | C24: 5 | D24: =IF(ISNUMBER(C24+SUM($B$3:$B$4)),C24+SUM($B$3:$B$4),NA()) -> 9.5 | E24: #DIV/0! | F24: =IF(ISNUMBER(E24+$B$5),E24+$B$5,NA()) -> #N/A | G24: =F24 -> #N/A | H24: =IFERROR(VLOOKUP(A24,'Capacity factor'!$L$7:$R$129,6,FALSE),"") -> 88.2
A25: Hanbit-6 | B25: KOR | C25: 5 | D25: =IF(ISNUMBER(C25+SUM($B$3:$B$4)),C25+SUM($B$3:$B$4),NA()) -> 9.5 | E25: 4244.7431 | F25: =IF(ISNUMBER(E25+$B$5),E25+$B$5,NA()) -> 4840.3731 | G25: =F25 -> 4840.3731 | H25: =IFERROR(VLOOKUP(A25,'Capacity factor'!$L$7:$R$129,6,FALSE),"") -> 85.1
A26: Hanbit-5 | B26: KOR | C26: 5 | D26: =IF(ISNUMBER(C26+SUM($B$3:$B$4)),C26+SUM($B$3:$B$4),NA()) -> 9.5 | E26: 4247.096 | F26: =IF(ISNUMBER(E26+$B$5),E26+$B$5,NA()) -> 4842.726 | G26: =F26 -> 4842.726 | H26: =IFERROR(VLOOKUP(A26,'Capacity factor'!$L$7:$R$129,6,FALSE),"") -> 79.2
A27: Tomari-3 | B27: JP | C27: 5 | D27: =IF(ISNUMBER(C27+SUM($B$3:$B$4)),C27+SUM($B$3:$B$4),NA()) -> 9.5 | E27: 3812.0106 | F27: =IF(ISNUMBER(E27+$B$5),E27+$B$5,NA()) -> 4407.6406 | G27: =F27 -> 4407.6406
A28: Shika-2 | B28: JP | C28: 5 | D28: =IF(ISNUMBER(C28+SUM($B$3:$B$4)),C28+SUM($B$3:$B$4),NA()) -> 9.5 | E28: 4607.2352 | F28: =IF(ISNUMBER(E28+$B$5),E28+$B$5,NA()) -> 5202.8652 | G28: =F28 -> 5202.8652
A29: Higashi Dori-1 | B29: JP | C29: 5 | D29: =IF(ISNUMBER(C29+SUM($B$3:$B$4)),C29+SUM($B$3:$B$4),NA()) -> 9.5 | E29: 4971.277 | F29: =IF(ISNUMBER(E29+$B$5),E29+$B$5,NA()) -> 5566.907 | G29: =F29 -> 5566.907
A30: Hamaoka-5 | B30: JP | C30: 5 | D30: =IF(ISNUMBER(C30+SUM($B$3:$B$4)),C30+SUM($B$3:$B$4),NA()) -> 9.5 | E30: 3536.9758 | F30: =IF(ISNUMBER(E30+$B$5),E30+$B$5,NA()) -> 4132.6058 | G30: =F30 -> 4132.6058
A31: Onagawa-3 | B31: JP | C31: 4 | D31: =IF(ISNUMBER(C31+SUM($B$3:$B$4)),C31+SUM($B$3:$B$4),NA()) -> 8.5 | E31: 4859.4197 | F31: =IF(ISNUMBER(E31+$B$5),E31+$B$5,NA()) -> 5455.0497 | G31: =F31 -> 5455.0497
A32: Hinkley Point C1 | B32: UK | C32: 15 | D32: =IF(ISNUMBER(C32+SUM($B$3:$B$4)),C32+SUM($B$3:$B$4),NA()) -> 19.5 | E32: 9313.741 | F32: =IF(ISNUMBER(E32+$B$5),E32+$B$5,NA()) -> 9909.371 | G32: =F32 -> 9909.371
A33: Hinkley Point C2 | B33: UK | C33: 15 | D33: =IF(ISNUMBER(C33+SUM($B$3:$B$4)),C33+SUM($B$3:$B$4),NA()) -> 19.5 | E33: 9313.741 | F33: =IF(ISNUMBER(E33+$B$5),E33+$B$5,NA()) -> 9909.371 | G33: =F33 -> 9909.371
A34: Turkey point 7 | B34: US | C34: #VALUE! | D34: =IF(ISNUMBER(C34+SUM($B$3:$B$4)),C34+SUM($B$3:$B$4),NA()) -> #N/A | E34: 4001.6883 | F34: =IF(ISNUMBER(E34+$B$5),E34+$B$5,NA()) -> 4597.3183 | G34: =F34 -> 4597.3183
A35: Turkey point 7* | B35: US | C35: #VALUE! | D35: =IF(ISNUMBER(C35+SUM($B$3:$B$4)),C35+SUM($B$3:$B$4),NA()) -> #N/A | E35: 3441.4353 | F35: =IF(ISNUMBER(E35+$B$5),E35+$B$5,NA()) -> 4037.0653 | G35: =F35 -> 4037.0653
A36: Turkey point 6 | B36: US | C36: #VALUE! | D36: =IF(ISNUMBER(C36+SUM($B$3:$B$4)),C36+SUM($B$3:$B$4),NA()) -> #N/A | E36: 3441.4353 | F36: =IF(ISNUMBER(E36+$B$5),E36+$B$5,NA()) -> 4037.0653 | G36: =F36 -> 4037.0653
A37: Fermi 3 | B37: US | C37: #VALUE! | D37: =IF(ISNUMBER(C37+SUM($B$3:$B$4)),C37+SUM($B$3:$B$4),NA()) -> #N/A | E37: 3611.8682 | F37: =IF(ISNUMBER(E37+$B$5),E37+$B$5,NA()) -> 4207.4982 | G37: =F37 -> 4207.4982
A38: Ohma 1 | B38: JP | C38: 22 | D38: =IF(ISNUMBER(C38+SUM($B$3:$B$4)),C38+SUM($B$3:$B$4),NA()) -> 26.5 | E38: #DIV/0! | F38: =IF(ISNUMBER(E38+$B$5),E38+$B$5,NA()) -> #N/A | G38: =F38 -> #N/A
A39: Shimane 3 | B39: JP | C39: 25 | D39: =IF(ISNUMBER(C39+SUM($B$3:$B$4)),C39+SUM($B$3:$B$4),NA()) -> 29.5 | E39: #DIV/0! | F39: =IF(ISNUMBER(E39+$B$5),E39+$B$5,NA()) -> #N/A | G39: =F39 -> #N/A
A40: Temelin 4 (Češka) | B40: CZ | C40: #VALUE! | D40: =IF(ISNUMBER(C40+SUM($B$3:$B$4)),C40+SUM($B$3:$B$4),NA()) -> #N/A | E40: 6545.6302 | F40: =IF(ISNUMBER(E40+$B$5),E40+$B$5,NA()) -> 7141.2602 | G40: =F40 -> 7141.2602
...

Sheet WACC
A1: STRUKTURA FINANCIRANJA | B1: Delež | C1: Ročnost | D1: Min | E1: Mean | F1: Max
A2: Lastniški kapital - mala vloga države | B2: 0 | D2: 0 | E2: 0 | F2: 0
A3: Lastniški kapital - velika vloga države | B3: 0.25 | D3: 0.014 | E3: 0.10486438 | F3: 0.20531985 | G3: VELIKA VLOGA DRŽAVE
A4: Izvozni kredit - velika vloga države | B4: 0.25 | C4: 18 | D4: -0.0062745098 | E4: 0.016431048 | F4: 0.041470588
A5: Krediti pri bankah z in brez državnega poroštva - velika vloga države | B5: 0.15 | C5: 20 | D5: -0.014588235 | E5: 0.023706842 | F5: 0.05977451
A6: Obveznice (dolžniški vrednostni papirji) - velika vloga države | B6: 0.35 | C6: 50 | D6: -0.0099215686 | E6: 0.020588235 | F6: 0.032254902
A7: Izvozni kredit | B7: 0 | D7: 0 | E7: 0 | F7: 0 | G7: MALA VLOGA DRŽAVE
A8: Krediti pri bankah z in brez državnega poroštva | B8: 0 | D8: 0 | E8: 0 | F8: 0
A9: Obveznice (dolžniški vrednostni papirji) | B9: 0 | D9: 0 | E9: 0 | F9: 0
A10: Strošek odobritve kredita, različne provizije pri izdaji | B10: 0.008

Sheet Stroški nadgradnje na 80 let
A1: Podaljšanje življenske dobe do 80 let
A2: Vzamemo povprečje iz slik Gen Energije
A3: Obdobje 41-60 let [EUR/kW/20 let] | B3: 629.5
A4: Obdobje 41-60 let [EUR/kW/leto] | B4: 0

Sheet O&M
H1: Povprečni podatki ameriških elektrarn [USD2022/MWh] | L1: Študija delež fixed vs flexible | M1: 175 | N1: USD/leto | P1: str 8 https://inldigitallibrary.inl.gov/sites/sti/sti/Sort_107010.pdf
H2: Single unit | I2: 26.09 | M2: =M1*(1000*M10) -> 218750000 | N2: letni fiksni stroški
H3: Multiple_unit | I3: 17.01 | M3: =M10*M9*8760 -> 9891500 | N3: proizvedene EE
H4: Podatek za JEK2 [USD2022/MWh] | I4: =I3*0.25+I2*0.75 -> 23.82 | J4: predpostavka, da se podaljša življenska doba JEK1 še za 20 let | M4: =M2/M3 -> 22.114947 | N4: USD/MWh fiksni
A5: Povp. fiksni O&M skozi vseh 80 let[EUR/kW] | B5: =I8 -> 155.99592 | C5: Share of Fiskni =%M 41-60 | D5: Izračun po deležih | E5: Average | F5: razmerja iz gen energija študije | H5: Podatek za JEK2 [EUR2022/MWh] | I5: 22.685714 | M5: 2.8 | N5: USD/MWh variabilni
A6: Fiksni O&M 0-20 [EUR/kW] | B6: =C6*B8 -> 73.409843 | C6: 0.3 | D6: =C6*D8 -> 73.409843 | E6: =AVERAGE(D6:D9) -> 155.99592 | H6: Podatek za JEK2 [EUR2024/MWh] | I6: 22.209314 | M6: =M4/SUM(M4:M5) -> 0.88761766 | N6: delež fiksnih
A7: Fiksni O&M 21-40 [EUR/kW] | B7: =B8*C7 -> 183.52461 | C7: 0.75 | D7: =C7*D8 -> 183.52461 | H7: Fiskni OM [EUR2024/MWh] | I7: =I6*M6 -> 19.71338 | M7: =M5/SUM(M4:M5) -> 0.11238234 | N7: delež variabilnih
A8: Fiksni O&M 41-60 [EUR/kW] | B8: =B5/(SUM(C6:C9))*4 -> 244.69948 | C8: 1 | D8: =B8 -> 244.69948 | H8: Fiskni OM [EUR2024/kW] | I8: =I7*M3/(M10*1000) -> 155.99592
A9: Fiksni O&M 61-80 [EUR/kW] | B9: =B8*C9 -> 122.34974 | C9: 0.5 | D9: =C9*D8 -> 122.34974 | H9: Variabilni OM [EUR2024/MWh] | I9: =I6*M7 -> 2.4959347 | M9: ='Capacity factor'!$B$5 -> 0.90333333 | N9: Capacity factor (za zdaj dokler ni končne vrednosti)
H10: Zmerni stroški v €/kWe leto - 2024 | I10: 205.70175 | M10: ='Inštalirana kapaciteta'!B2 -> 1250 | N10: povprečna moč JE
A11: Razmerje 75 % in 50 % (Table 38 - https://inldigitallibrary.inl.gov/sites/sti/sti/Sort_107010.pdf) | B11: =I11 -> 239.78947 | C11: =I10 -> 205.70175 | D11: =B11/C11 -> 1.1657143 | E11: Max | H11: Konzervativni stroški v €/kWe leto - 2024 | I11: 239.78947
A12: Razmerje 25% in 50% (Table 38 - https://inldigitallibrary.inl.gov/sites/sti/sti/Sort_107010.pdf) | B12: =I10 -> 205.70175 | C12: =I12 -> 148.10526 | D12: =C12/B12 -> 0.72 | E12: Min | H12: Napredni stroški v €/kWe leto - 2024 | I12: 148.10526
A16: Variabilni O&M stroški [EUR/MWh] | B16: =I9 -> 2.4959347
A18: Stroški obratovanja in vzdrževanja | B18: Min | C18: Srednja vrednost | D18: Max
A19: Fiksni O&M 1-20 let [EUR/kW] | B19: =$D$12*C19 -> 52.855087 | C19: =B6 -> 73.409843 | D19: =$D$11*C19 -> 85.574902
A20: Fiksni O&M 21-40 let [EUR/kW] | B20: =$D$12*C20 -> 132.13772 | C20: =B7 -> 183.52461 | D20: =$D$11*C20 -> 213.93726
A21: Fiksni O&M 41-60 let [EUR/kW] | B21: =$D$12*C21 -> 176.18362 | C21: =B8 -> 244.69948 | D21: =$D$11*C21 -> 285.24967
A22: Fiksni O&M 61-80 let [EUR/kW] | B22: =$D$12*C22 -> 88.091811 | C22: =B9 -> 122.34974 | D22: =$D$11*C22 -> 142.62484
A23: Real escalation rate [%/year] | B23: 0.005
A24: =A16 -> Variabilni O&M stroški [EUR/MWh] | B24: =C24*D12 -> 1.7970729 | C24: =B16 -> 2.4959347 | D24: =C24*D11 -> 2.9095467
A25: Verjetnost, da se pojavijo vrednosti desno od povprečja [%] | B25: 0.55
A26: Verjetnost, da se pojavijo vrednosti levo od povprečja [%] | B26: =1-B25 -> 0.45
A27: Delež fiksnih O&M stroškov v času gradnje glede na povprečne O&M stroške za časa obratovanja [%] | B27: 0 | C27: Za zdaj ni O&M stroškov tekom gradnje, sam so notri v OCC
A28: Povprečni stroški O&M skozi 80 let [EUR/kW] | B28: =$B$5 -> 155.99592

Sheet Fuel cost
A1: Fuel cost min [EUR2024/MWh] | B1: 6.46
A2: Fuel cost mean [EUR2024/MWh] | B2: 8.23
A3: Fuel cost max [EUR2024/MWh] | B3: 9.52
A4: Real cost escalation [%] | B4: 0
A5: Verjetnost, da se pojavijo vrednosti levo od povprečja [%] | B5: =1-B6 -> 0.45
A6: Verjetnost, da se pojavijo vrednosti desno od povprečja [%] | B6: 0.55

Sheet Extraordinary repairs
A1: Hitre samodejne ustavitve v obdobju delovanju 1983-2023 | B1: 82 | C1: JEK1 vir | D1: ! VKLJUČEN V DRUGIH STROŠKIH, ZATO TRENUTNO 0
A2: Hitre ročne ustavitve v obdobju delovanju 1983-2023 | B2: 5 | C2: JEK1 vir
A3: Prisilne ustavitve v obdobju delovanju 1983-2023 | B3: 27 | C3: JEK1 vir
A4: Skupaj nenačrtovanih ustavitev | B4: =SUM(B1:B3) -> 114
A5: Število nepričakovanih izpadov na leto | B5: 0
A6: Strošek nepričakovanega remonta - tehnično popravilo [EUR] | B6: 0
A7: Strošek nepričakovanega remonta - izgube zaradi potrebe po nakupu EE iz trga in izgube nevariabilne cene stroškovne cene EE [EUR] | B7: 0
A8: Skupen strošek nepričakovanega remonta [EUR] | B8: =SUM(B6:B7) -> 0
A9: Fiksna stroškovna cena proizvodnje EE, zmanjšana za variabilne stroške (tj. goriva) [EUR/MWh] | B9: =43.74-8 -> 35.74 | C9: JEK2 vir
A10: Kolikšen delež leta v povprečju takšen dogodek traja oz. faktor prisilne ustavitve [delež leta] | B10: 0.0116 | C10: JEK1 vir
A11: Povprečen capacity factor [%] | B11: ='Capacity factor'!$B$5 -> 0.90333333 | C11: Zgodovinski podatki za vse zahodne JE
A12: Cost escalation rate [%] | B12: 0

Sheet Stroški odpadkov
A1: 40 LET | K1: Escalation rate - MZPP | L1: 0.005 | N1: Finančni podatki | R1: JEK2 - Capacity factor - GEN-E | S1: NEK - Capacity factor - GEN-E | T1: Capacity faktor - MZPP | U1: Ur v letu dni
A2: Jedrska elektrarna | B2: Moč reaktorja (MW) | C2: Cena ravnanja z odpadki 2020-2023 (mio. €) | D2: Cena ravnanja z odpadki 2024 (mio. €) | E2: Cena ravnanja z odpadki 2024 [EUR] | F2: Cena ravnanja z odpadki povečana za escalation rate (y + 40) | G2: Letno plačilo, da v 40 letih pridemo do končne investicijske vrednosti | H2: Preverba, da prideš do istih cifer | I2: Strošek (€/MW/leto) | J2: Strošek (€/MWh) | K2: Povprečje let | L2: 40 | N2: Inflacija iz leta 2020 do sredine 2024 | O2: Inflacija iz leta 2021 do sredine 2024 | P2: Inflacija iz leta 2023 do sredine 2024 | Q2: Inflacija iz leta 2022 do sredine 2024 | R2: 0.93 | S2: 0.9 | T2: ='Capacity factor'!$B$5 -> 0.90333333 | U2: 8760
A3: Loviisa-2 (Finska) | B3: 507 | C3: =L17*(B3/SUM(B3:B4)) -> 426.15274 | D3: =C3*$Q$3 -> 417.20353 | E3: =D3*1000000 -> 4.1720353e+08 | F3: =FV($L$1,$L$2,,-E3,1) -> 5.0931967e+08 | G3: =PMT($L$3,$L$2,,-F3,1) -> 7809092.4 | H3: {=SUM(G3*(1+$L$3)^ROW(INDIRECT("1:"&$L$2)))} -> 5.0931967e+08 | I3: =G3/(SUM(B3)) -> 15402.549 | J3: =I3/($T$2*$U$2) -> 1.9464375 | K3: Interest rate - MZPP | L3: 0.0225 | N3: =1.34 -> 1.34 | O3: =1.127 -> 1.127 | P3: 1.002 | Q3: 0.979 | R3: Escalation rate - GEN | S3: 0
A4: Olkiluoto-3 (Finska) | B4: 1575 | C4: =L17*(B4/SUM(B3:B4)) -> 1323.8473 | D4: =C4*$Q$3 -> 1296.0465 | E4: =D4*1000000 -> 1.2960465e+09 | F4: =FV($L$1,$L$2,,-E4,1) -> 1.5822061e+09 | G4: =PMT($L$3,$L$2,,-F4,1) -> 24259015 | H4: {=SUM(G4*(1+$L$3)^ROW(INDIRECT("1:"&$L$2)))} -> 1.5822061e+09 | I4: =G4/(SUM(B4)) -> 15402.549 | J4: =I4/($T$2*$U$2) -> 1.9464375 | R4: Interest rate - GEN | S4: =0.015 -> 0.015
A5: =A3 -> Loviisa-2 (Finska) | I5: =I3 -> 15402.549 | J5: =I5/($T$2*$U$2) -> 1.9464375 | K5: Strošek (€/MW/leto) | M5: Strošek (€/MWh)
A6: =A4 -> Olkiluoto-3 (Finska) | I6: =I4 -> 15402.549 | J6: =I6/($T$2*$U$2) -> 1.9464375 | K6: Min | L6: =MIN(I3:I17) -> 14349.779 | M6: Min | N6: =MIN(J3:J17) -> 1.8133977
A7: Barseback 2 (Švedska) | B7: 600 | C7: =$L$20*(B7/SUM($B$7:$B$12)) -> 469.8521 | D7: =C7*$Q$3 -> 459.98521 | E7: =D7*1000000 -> 4.5998521e+08 | F7: =FV($L$1,$L$2,,-E7,1) -> 5.6154729e+08 | G7: =PMT($L$3,$L$2,,-F7,1) -> 8609867.2 | H7: {=SUM(G7*(1+$L$3)^ROW(INDIRECT("1:"&$L$2)))} -> 5.6154729e+08 | I7: =G7/(SUM(B7)) -> 14349.779 | J7: =I7/($T$2*$U$2) -> 1.8133977 | K7: Average | L7: =AVERAGE(I3:I17) -> 20581.443 | M7: Average | N7: =AVERAGE(J3:J17) -> 2.5951395
A8: Forsmark 2 (Švedska) | B8: 1121 | C8: =$L$20*(B8/SUM($B$7:$B$12)) -> 877.84035 | D8: =C8*$Q$3 -> 859.4057 | E8: =D8*1000000 -> 8.594057e+08 | F8: =FV($L$1,$L$2,,-E8,1) -> 1.0491575e+09 | G8: =PMT($L$3,$L$2,,-F8,1) -> 16086102 | H8: {=SUM(G8*(1+$L$3)^ROW(INDIRECT("1:"&$L$2)))} -> 1.0491575e+09 | I8: =G8/(SUM(B8)) -> 14349.779 | J8: =I8/($T$2*$U$2) -> 1.8133977 | K8: Max | L8: =MAX(I3:I17) -> 58991.718 | M8: Max | N8: =MAX(J3:J17) -> 7.4548499
A9: Forsmark 3 (Švedska) | B9: 1172 | C9: =$L$20*(B9/SUM($B$7:$B$12)) -> 917.77777 | D9: =C9*$Q$3 -> 898.50444 | E9: =D9*1000000 -> 8.9850444e+08 | F9: =FV($L$1,$L$2,,-E9,1) -> 1.096889e+09 | G9: =PMT($L$3,$L$2,,-F9,1) -> 16817941 | H9: {=SUM(G9*(1+$L$3)^ROW(INDIRECT("1:"&$L$2)))} -> 1.096889e+09 | I9: =G9/(SUM(B9)) -> 14349.779 | J9: =I9/($T$2*$U$2) -> 1.8133977 | K9: Min distribucije | L9: =$L$6 -> 14349.779 | M9: Min distribucije | N9: =$N$6 -> 1.8133977
A10: Oskarshamn 3 (Švedska) | B10: 1400 | C10: =$L$20*(B10/SUM($B$7:$B$12)) -> 1096.3216 | D10: =C10*$Q$3 -> 1073.2988 | E10: =D10*1000000 -> 1.0732988e+09 | F10: =FV($L$1,$L$2,,-E10,1) -> 1.310277e+09 | G10: =PMT($L$3,$L$2,,-F10,1) -> 20089690 | H10: {=SUM(G10*(1+$L$3)^ROW(INDIRECT("1:"&$L$2)))} -> 1.310277e+09 | I10: =G10/(SUM(B10)) -> 14349.779 | J10: =I10/($T$2*$U$2) -> 1.8133977 | K10: Max distribucije | L10: =$L$8 -> 58991.718 | M10: Max distribucije | N10: =$N$8 -> 7.4548499
A11: Ringhals 3 (Švedska) | B11: 1081 | C11: =$L$20*(B11/SUM($B$7:$B$12)) -> 846.51687 | D11: =C11*$Q$3 -> 828.74002 | E11: =D11*1000000 -> 8.2874002e+08 | F11: =FV($L$1,$L$2,,-E11,1) -> 1.011721e+09 | G11: =PMT($L$3,$L$2,,-F11,1) -> 15512111 | H11: {=SUM(G11*(1+$L$3)^ROW(INDIRECT("1:"&$L$2)))} -> 1.011721e+09 | I11: =G11/(SUM(B11)) -> 14349.779 | J11: =I11/($T$2*$U$2) -> 1.8133977 | K11: * povprečje treh vrednosti | L11: =AVERAGE((306+147),(317+172),(394+198)) -> 511.33333 | M11: ** Delitev moči NEK na dva dela
A12: Ringhals 4 (Švedska) | B12: 1130 | C12: =$L$20*(B12/SUM($B$7:$B$12)) -> 884.88813 | D12: =C12*$Q$3 -> 866.30548 | E12: =D12*1000000 -> 8.6630548e+08 | F12: =FV($L$1,$L$2,,-E12,1) -> 1.0575807e+09 | G12: =PMT($L$3,$L$2,,-F12,1) -> 16215250 | H12: {=SUM(G12*(1+$L$3)^ROW(INDIRECT("1:"&$L$2)))} -> 1.0575807e+09 | I12: =G12/(SUM(B12)) -> 14349.779 | J12: =I12/($T$2*$U$2) -> 1.8133977 | K12: Kak delež stroškov ostane pri švicarjih | L12: 0.5
A13: JEK1 | B13: 696 | C13: 1845 (2024) | D13: =1845 -> 1845 | E13: =D13*1000000 -> 1845000000 | F13: =FV($L$1,$L$2,,-E13,1) -> 2.2523654e+09 | G13: =PMT($L$3,$L$2,,-F13,1) -> 34534165 | H13: {=SUM(G13*(1+$L$3)^ROW(INDIRECT("1:"&$L$2)))} -> 2.2523654e+09 | I13: =G13/(SUM(B13)) -> 49618.053 | J13: =I13/($S$2*$U$2) -> 6.2935125
A14: JEK2* | B14: =1250 -> 1250 | C14: 3227 (2024) | D14: =3227*C74 -> 1041.5861 | E14: =D14*1000000 -> 1.0415861e+09 | F14: =FV($S$3,$L$2,,-E14,1) -> 1.0415861e+09 | G14: =PMT($S$4,$L$2,,-F14,1) -> 18909767 | H14: {=SUM(G14*(1+$S$4)^ROW(INDIRECT("1:"&$L$2)))} -> 1.0415861e+09 | I14: =G14/(SUM(B14)) -> 15127.814 | J14: =I14/($R$2*$U$2) -> 1.8569026
A15: JEK2* | B15: =1250 -> 1250 | C15: 3227 (2024) | D15: =3227*C74 -> 1041.5861 | E15: =D15*1000000 -> 1.0415861e+09 | F15: =FV($S$3,$L$2,,-E15,1) -> 1.0415861e+09 | G15: =PMT($S$4,$L$2,,-F15,1) -> 18909767 | H15: {=SUM(G15*(1+$S$4)^ROW(INDIRECT("1:"&$L$2)))} -> 1.0415861e+09 | I15: =G15/(SUM(B15)) -> 15127.814 | J15: =I15/($R$2*$U$2) -> 1.8569026 | K15: Strošek investicije Finske - celoten | L15: 7000 | M15: 221 milijard Švedskih kron (2022)
A16: Gosgen (Švica) | B16: 1010 | C16: 4751 (2020) | D16: =4751*N3*L12 -> 3183.17 | E16: =D16*1000000 -> 3183170000 | F16: =FV($L$1,$L$2,,-E16,1) -> 3.8859956e+09 | G16: =PMT($L$3,$L$2,,-F16,1) -> 59581635 | H16: {=SUM(G16*(1+$L$3)^ROW(INDIRECT("1:"&$L$2)))} -> 3.8859956e+09 | I16: =G16/(SUM(B16)) -> 58991.718 | J16: =I16/($T$2*$U$2) -> 7.4548499 | K16: Koliko prevzamejo mlajše elektrarne (2/5) | L16: 0.25 | M16: Pretvornik valute v €
A17: Nova češka JE | I17: =$D$87 -> 22147.376 | J17: =I17/($T$2*$U$2) -> 2.7987889 | K17: Strošek investicije Finske - novejše | L17: =L16*L15 -> 1750 | M17: 10.62
A18: 60 LET | K18: Strošek investicije Švedske | L18: =M19 -> 20372.787 | M18: Skupna cena ravnanja z odpadki v mio. € (2024)
A19: =A2 -> Jedrska elektrarna | B19: =B2 -> Moč reaktorja (MW) | C19: =C2 -> Cena ravnanja z odpadki 2020-2023 (mio. €) | D19: =D2 -> Cena ravnanja z odpadki 2024 (mio. €) | E19: =E2 -> Cena ravnanja z odpadki 2024 [EUR] | F19: Cena razgradnje povečana za escalation rate (y + 60) | G19: Letno plačilo, da v 60 letih pridemo do končne investicijske vrednosti | H19: Preverba, da prideš do istih cifer | I19: Strošek (€/MW/leto) | J19: Strošek (€/MWh) | K19: =K16 -> Koliko prevzamejo mlajše elektrarne (2/5) | L19: =L16 -> 0.25 | M19: =(221000000000/10.62)/1000000*Q3 -> 20372.787
A20: Loviisa-2 (Finska) | B20: 507 | C20: =$L$17*(B20/SUM(B20:B21)) -> 426.15274 | D20: =C20*$Q$3 -> 417.20353 | E20: =D20*1000000 -> 4.1720353e+08 | F20: =FV($L$1,$L$22,,-E20,1) -> 5.6274505e+08 | G20: =PMT($L$3,$L$22,,-F20,1) -> 4422338.1 | H20: {=SUM(G20*(1+$L$3)^ROW(INDIRECT("1:"&$L$22)))} -> 5.6274505e+08 | I20: =G20/(SUM(B20)) -> 8722.5604 | J20: =I20/($T$2*$U$2) -> 1.1022798 | K20: Strošek investicije Švedska - novejše | L20: =L19*L18 -> 5093.1968
A21: Olkiluoto-3 (Finska) | B21: 1575 | C21: =$L$17*(B21/SUM(B20:B21)) -> 1323.8473 | D21: =C21*$Q$3 -> 1296.0465 | E21: =D21*1000000 -> 1.2960465e+09 | F21: =FV($L$1,$L$22,,-E21,1) -> 1.7481725e+09 | G21: =PMT($L$3,$L$22,,-F21,1) -> 13738033 | H21: {=SUM(G21*(1+$L$3)^ROW(INDIRECT("1:"&$L$22)))} -> 1.7481725e+09 | I21: =G21/(SUM(B21)) -> 8722.5604 | J21: =I21/($T$2*$U$2) -> 1.1022798
A22: =A20 -> Loviisa-2 (Finska) | I22: =I20 -> 8722.5604 | J22: =I22/($T$2*$U$2) -> 1.1022798 | K22: Leta | L22: 60
A23: =A21 -> Olkiluoto-3 (Finska) | I23: =I21 -> 8722.5604 | J23: =I23/($T$2*$U$2) -> 1.1022798 | K23: Strošek (€/MW/leto) | M23: Strošek (€/MWh)
A24: Barseback 2 (Švedska) | B24: 600 | C24: =$L$20*(B24/SUM($B$7:$B$12)) -> 469.8521 | D24: =C24*$Q$3 -> 459.98521 | E24: =D24*1000000 -> 4.5998521e+08 | F24: =FV($L$1,$L$22,,-E24,1) -> 6.2045112e+08 | G24: =PMT($L$3,$L$22,,-F24,1) -> 4875821.9 | H24: {=SUM(G24*(1+$L$3)^ROW(INDIRECT("1:"&$L$22)))} -> 6.2045112e+08 | I24: =G24/(SUM(B24)) -> 8126.3699 | J24: =I24/($T$2*$U$2) -> 1.0269385 | K24: Min | L24: =MIN(I20:I34) -> 8126.3699 | M24: Min | N24: =MIN(J20:J34) -> 1.0269385
A25: Forsmark 2 (Švedska) | B25: 1121 | C25: =$L$20*(B25/SUM($B$7:$B$12)) -> 877.84035 | D25: =C25*$Q$3 -> 859.4057 | E25: =D25*1000000 -> 8.594057e+08 | F25: =FV($L$1,$L$22,,-E25,1) -> 1.1592095e+09 | G25: =PMT($L$3,$L$22,,-F25,1) -> 9109660.7 | H25: {=SUM(G25*(1+$L$3)^ROW(INDIRECT("1:"&$L$22)))} -> 1.1592095e+09 | I25: =G25/(SUM(B25)) -> 8126.3699 | J25: =I25/($T$2*$U$2) -> 1.0269385 | K25: Average | L25: =AVERAGE(I20:I34) -> 11650.808 | M25: Average | N25: =AVERAGE(J20:J34) -> 1.4690801
A26: Forsmark 3 (Švedska) | B26: 1172 | C26: =$L$20*(B26/SUM($B$7:$B$12)) -> 917.77777 | D26: =C26*$Q$3 -> 898.50444 | E26: =D26*1000000 -> 8.9850444e+08 | F26: =FV($L$1,$L$22,,-E26,1) -> 1.2119479e+09 | G26: =PMT($L$3,$L$22,,-F26,1) -> 9524105.5 | H26: {=SUM(G26*(1+$L$3)^ROW(INDIRECT("1:"&$L$22)))} -> 1.2119479e+09 | I26: =G26/(SUM(B26)) -> 8126.3699 | J26: =I26/($T$2*$U$2) -> 1.0269385 | K26: Max | L26: =MAX(I20:I34) -> 33407.381 | M26: Max | N26: =MAX(J20:J34) -> 4.2217284
A27: Oskarshamn 3 (Švedska) | B27: 1400 | C27: =$L$20*(B27/SUM($B$7:$B$12)) -> 1096.3216 | D27: =C27*$Q$3 -> 1073.2988 | E27: =D27*1000000 -> 1.0732988e+09 | F27: =FV($L$1,$L$22,,-E27,1) -> 1.4477193e+09 | G27: =PMT($L$3,$L$22,,-F27,1) -> 11376918 | H27: {=SUM(G27*(1+$L$3)^ROW(INDIRECT("1:"&$L$22)))} -> 1.4477193e+09 | I27: =G27/(SUM(B27)) -> 8126.3699 | J27: =I27/($T$2*$U$2) -> 1.0269385 | K27: Min distribucije | L27: =$L$24 -> 8126.3699 | M27: Min distribucije | N27: =$N$24 -> 1.0269385
A28: Ringhals 3 (Švedska) | B28: 1081 | C28: =$L$20*(B28/SUM($B$7:$B$12)) -> 846.51687 | D28: =C28*$Q$3 -> 828.74002 | E28: =D28*1000000 -> 8.2874002e+08 | F28: =FV($L$1,$L$22,,-E28,1) -> 1.1178461e+09 | G28: =PMT($L$3,$L$22,,-F28,1) -> 8784605.9 | H28: {=SUM(G28*(1+$L$3)^ROW(INDIRECT("1:"&$L$22)))} -> 1.1178461e+09 | I28: =G28/(SUM(B28)) -> 8126.3699 | J28: =I28/($T$2*$U$2) -> 1.0269385 | K28: Max distribucije | L28: =$L$8 -> 58991.718 | M28: Max distribucije | N28: =$N$26 -> 4.2217284
A29: Ringhals 4 (Švedska) | B29: 1130 | C29: =$L$20*(B29/SUM($B$7:$B$12)) -> 884.88813 | D29: =C29*$Q$3 -> 866.30548 | E29: =D29*1000000 -> 8.6630548e+08 | F29: =FV($L$1,$L$22,,-E29,1) -> 1.1685163e+09 | G29: =PMT($L$3,$L$22,,-F29,1) -> 9182798 | H29: {=SUM(G29*(1+$L$3)^ROW(INDIRECT("1:"&$L$22)))} -> 1.1685163e+09 | I29: =G29/(SUM(B29)) -> 8126.3699 | J29: =I29/($T$2*$U$2) -> 1.0269385
A30: JEK1 | B30: 696 | C30: =C13 -> 1845 (2024) | D30: =D13 -> 1845 | E30: =D30*1000000 -> 1845000000 | F30: =FV($L$1,$L$22,,-E30,1) -> 2.4886285e+09 | G30: =PMT($L$3,$L$22,,-F30,1) -> 19556915 | H30: {=SUM(G30*(1+$L$3)^ROW(INDIRECT("1:"&$L$22)))} -> 2.4886285e+09 | I30: =G30/(SUM(B30)) -> 28099.015 | J30: =I30/($S$2*$U$2) -> 3.5640557 | K30: * povprečje treh vrednosti | L30: =AVERAGE((306+147),(317+172),(394+198)) -> 511.33333 | M30: ** Delitev moči NEK na dva dela
A31: JEK2* | B31: =1250 -> 1250 | C31: 3227 (2024) | D31: =3227*C74 -> 1041.5861 | E31: =D31*1000000 -> 1.0415861e+09 | F31: =FV($S$3,$L$22,,-E31,1) -> 1.0415861e+09 | G31: =PMT($S$4,$L$22,,-F31,1) -> 10665665 | H31: {=SUM(G31*(1+$S$4)^ROW(INDIRECT("1:"&$L$22)))} -> 1.0415861e+09 | I31: =G31/(SUM(B31)) -> 8532.532 | J31: =I31/($R$2*$U$2) -> 1.0473477
A32: JEK2* | B32: =1250 -> 1250 | C32: 3227 (2024) | D32: =3227*C74 -> 1041.5861 | E32: =D32*1000000 -> 1.0415861e+09 | F32: =FV($S$3,$L$22,,-E32,1) -> 1.0415861e+09 | G32: =PMT($S$4,$L$22,,-F32,1) -> 10665665 | H32: {=SUM(G32*(1+$S$4)^ROW(INDIRECT("1:"&$L$22)))} -> 1.0415861e+09 | I32: =G32/(SUM(B32)) -> 8532.532 | J32: =I32/($R$2*$U$2) -> 1.0473477
A33: Gosgen (Švica) | B33: 1010 | C33: 4751 (2020) | D33: =4751*$N$3*$L$12 -> 3183.17 | E33: =D33*1000000 -> 3183170000 | F33: =FV($L$1,$L$22,,-E33,1) -> 4.2936193e+09 | G33: =PMT($L$3,$L$22,,-F33,1) -> 33741455 | H33: {=SUM(G33*(1+$L$3)^ROW(INDIRECT("1:"&$L$22)))} -> 4.2936193e+09 | I33: =G33/(SUM(B33)) -> 33407.381 | J33: =I33/($T$2*$U$2) -> 4.2217284
A34: Nova češka JE | I34: =$C$87 -> 12542.198 | J34: =I34/($T$2*$U$2) -> 1.5849718
A35: 80 LET
A36: =A19 -> Jedrska elektrarna | B36: =B19 -> Moč reaktorja (MW) | C36: =C19 -> Cena ravnanja z odpadki 2020-2023 (mio. €) | D36: =D19 -> Cena ravnanja z odpadki 2024 (mio. €) | E36: =E19 -> Cena ravnanja z odpadki 2024 [EUR] | F36: Cena razgradnje povečana za escalation rate (y + 80) | G36: Letno plačilo, da v 80 letih pridemo do končne investicijske vrednosti | H36: Preverba, da prideš do istih cifer | I36: Strošek (€/MW/leto) | J36: Strošek (€/MWh) | K36: Leta | L36: 80
A37: Loviisa-2 (Finska) | B37: 507 | C37: =$L$17*(B37/SUM(B37:B38)) -> 426.15274 | D37: =C37*$Q$3 -> 417.20353 | E37: =D37*1000000 -> 4.1720353e+08 | F37: =FV($L$1,$L$36,,-E37,1) -> 6.2177451e+08 | G37: =PMT($L$3,$L$36,,-F37,1) -> 2775187.9 | H37: {=SUM(G37*(1+$L$3)^ROW(INDIRECT("1:"&$L$36)))} -> 6.2177451e+08 | I37: =G37/(SUM(B37)) -> 5473.7435 | J37: =I37/($T$2*$U$2) -> 0.69172313 | K37: Strošek (€/MW/leto) | M37: Strošek (€/MWh)
A38: Olkiluoto-3 (Finska) | B38: 1575 | C38: =$L$17*(B38/SUM(B37:B38)) -> 1323.8473 | D38: =C38*$Q$3 -> 1296.0465 | E38: =D38*1000000 -> 1.2960465e+09 | F38: =FV($L$1,$L$36,,-E38,1) -> 1.931548e+09 | G38: =PMT($L$3,$L$36,,-F38,1) -> 8621145.9 | H38: {=SUM(G38*(1+$L$3)^ROW(INDIRECT("1:"&$L$36)))} -> 1.931548e+09 | I38: =G38/(SUM(B38)) -> 5473.7435 | J38: =I38/($T$2*$U$2) -> 0.69172313 | K38: Min | L38: =MIN(I37:I51) -> 5099.6109 | M38: Min | N38: =MIN(J37:J51) -> 0.64444357 | O38: GEN-E (delež za odpadke) - Strošek (€/MWh)
A39: =A37 -> Loviisa-2 (Finska) | I39: =I37 -> 5473.7435 | J39: =I39/($T$2*$U$2) -> 0.69172313 | K39: Average | L39: =AVERAGE(I37:I51) -> 7314.1829 | M39: Average | N39: =AVERAGE(J37:J51) -> 0.92034361 | O39: =2*0.3 -> 0.6
A40: =A38 -> Olkiluoto-3 (Finska) | I40: =I38 -> 5473.7435 | J40: =I40/($T$2*$U$2) -> 0.69172313 | K40: Max | L40: =MAX(I37:I51) -> 20964.421 | M40: Max | N40: =MAX(J37:J51) -> 2.6492976
...

Sheet Stroški razgradnje
A1: 40 LET | K1: Escalation rate - MZPP | L1: 0.005 | N1: Finančni podatki | Q1: JEK2 - Capacity factor - GEN-E | R1: NEK - Capacity factor - GEN-E | S1: Capacity faktor - MZPP | T1: Ur v letu dni
A2: Jedrska elektrarna | B2: Moč reaktorja (MW) | C2: Cena razgradnje 2020-2023 (mio. €) | D2: Cena razgradnje 2024 (mio. €) | E2: Cena razgradnje 2024 [EUR] | F2: Cena razgradnje povečana za escalation rate (y + 40) | G2: Letno plačilo, da v 40 letih pridemo do končne investicijske vrednosti | H2: Preverba, da prideš do istih cifer | I2: Strošek (€/MW/leto) | J2: Strošek (€/MWh) | K2: Povprečje let | L2: 40 | N2: Inflacija iz leta 2020 do sredine 2024 | O2: Inflacija iz leta 2021 do sredine 2024 | P2: Inflacija iz leta 2023 do sredine 2024 | Q2: 0.93 | R2: ='Stroški odpadkov'!$S$2 -> 0.9 | S2: ='Capacity factor'!$B$5 -> 0.90333333 | T2: 8760
A3: Fessenheim 1,2 (Francija) | B3: 1840 | C3: 808 (2021) | D3: =808*O3 -> 910.616 | E3: =D3*1000000 -> 910616000 | F3: =FV($L$1,$L$2,,-E3,1) -> 1.1116748e+09 | G3: =PMT($L$3,$L$2,,-F3,1) -> 17044641 | H3: {=SUM(G3*(1+$L$3)^ROW(INDIRECT("1:"&$L$2)))} -> 1.1116748e+09 | I3: =G3/B3 -> 9263.3919 | J3: =I3/($T$2*$S$2) -> 1.1706253 | K3: Interest rate - MZPP | L3: 0.0225 | N3: =1.34 -> 1.34 | O3: =1.127 -> 1.127 | P3: 1.002 | Q3: Escalation rate - GEN | R3: 0
A4: Chooz-A (Francija) | B4: 320 | C4: 280 (2021) | D4: =280*O3 -> 315.56 | E4: =D4*1000000 -> 315560000 | F4: =FV($L$1,$L$2,,-E4,1) -> 3.8523383e+08 | G4: =PMT($L$3,$L$2,,-F4,1) -> 5906558.8 | H4: {=SUM(G4*(1+$L$3)^ROW(INDIRECT("1:"&$L$2)))} -> 3.8523383e+08 | I4: =G4/B4 -> 18457.996 | J4: =I4/($T$2*$S$2) -> 2.3325578 | Q4: Interest rate - GEN | R4: =0.015 -> 0.015
A5: Super-Phenix (Francija) | B5: 1242 | C5: 520.5 (2021) | D5: =520.5*O3 -> 586.6035 | E5: =D5*1000000 -> 586603500 | F5: =FV($L$1,$L$2,,-E5,1) -> 7.1612217e+08 | G5: =PMT($L$3,$L$2,,-F5,1) -> 10979871 | H5: {=SUM(G5*(1+$L$3)^ROW(INDIRECT("1:"&$L$2)))} -> 7.1612217e+08 | I5: =G5/B5 -> 8840.4758 | J5: =I5/($T$2*$S$2) -> 1.1171809 | K5: Strošek (€/MW/leto) | M5: Strošek (€/MWh)
A6: Obrigheim (Nemčija) | B6: 340 | C6: 630.4 (2020) | D6: =630.4*N3 -> 844.736 | E6: =D6*1000000 -> 844736000 | F6: =FV($L$1,$L$2,,-E6,1) -> 1.0312488e+09 | G6: =PMT($L$3,$L$2,,-F6,1) -> 15811519 | H6: {=SUM(G6*(1+$L$3)^ROW(INDIRECT("1:"&$L$2)))} -> 1.0312488e+09 | I6: =G6/B6 -> 46504.467 | J6: =I6/($T$2*$S$2) -> 5.8768219 | K6: Min | L6: =MIN(I3:I13) -> 8840.4758 | M6: Min | N6: =MIN(J3:J14) -> 1.1171809
A7: Muelheim-Kaerlich (Nemčija) | B7: 1219 | C7: 761.7 (2020) | D7: =761.7*N3 -> 1020.678 | E7: =D7*1000000 -> 1.020678e+09 | F7: =FV($L$1,$L$2,,-E7,1) -> 1.2460378e+09 | G7: =PMT($L$3,$L$2,,-F7,1) -> 19104749 | H7: {=SUM(G7*(1+$L$3)^ROW(INDIRECT("1:"&$L$2)))} -> 1.2460378e+09 | I7: =G7/B7 -> 15672.477 | J7: =I7/($T$2*$S$2) -> 1.9805485 | K7: Average | L7: =AVERAGE(I3:I13) -> 25490.7 | M7: Average | N7: =AVERAGE(J3:J14) -> 3.4129571
A8: Greifswald 1-5 (Nemčija) | B8: =5*408 -> 2040 | C8: 4202.4 (2020) | D8: =4202.4*N3 -> 5631.216 | E8: =D8*1000000 -> 5.631216e+09 | F8: =FV($L$1,$L$2,,-E8,1) -> 6.874556e+09 | G8: =PMT($L$3,$L$2,,-F8,1) -> 1.0540344e+08 | H8: {=SUM(G8*(1+$L$3)^ROW(INDIRECT("1:"&$L$2)))} -> 6.874556e+09 | I8: =G8/B8 -> 51668.351 | J8: =I8/($T$2*$S$2) -> 6.5293878 | K8: Max | L8: =MAX(I3:I13) -> 51668.351 | M8: Max | N8: =MAX(J3:J14) -> 6.5293878
A9: Beznau 1, 2 (Švica) | B9: =2*365 -> 730 | C9: 887,5 (2020) | D9: =887.5*N3 -> 1189.25 | E9: =D9*1000000 -> 1189250000 | F9: =FV($L$1,$L$2,,-E9,1) -> 1.4518295e+09 | G9: =PMT($L$3,$L$2,,-F9,1) -> 22260030 | H9: {=SUM(G9*(1+$L$3)^ROW(INDIRECT("1:"&$L$2)))} -> 1.4518295e+09 | I9: =G9/B9 -> 30493.192 | J9: =I9/($T$2*$S$2) -> 3.853459 | K9: Min distribucije | L9: =$L$6 -> 8840.4758 | M9: Min distribucije | N9: =$N$6 -> 1.1171809
A10: Gosgen (Švica) | B10: 1010 | C10: 835.2 (2020) | D10: =835.2*N3 -> 1119.168 | E10: =D10*1000000 -> 1.119168e+09 | F10: =FV($L$1,$L$2,,-E10,1) -> 1.3662738e+09 | G10: =PMT($L$3,$L$2,,-F10,1) -> 20948256 | H10: {=SUM(G10*(1+$L$3)^ROW(INDIRECT("1:"&$L$2)))} -> 1.3662738e+09 | I10: =G10/B10 -> 20740.847 | J10: =I10/($T$2*$S$2) -> 2.6210442 | K10: Max distribucije | L10: =$L$8 -> 51668.351 | M10: Max distribucije | N10: =$N$8 -> 6.5293878
A11: JEK1 | B11: 696 | C11: 568 (2024) | D11: =568 -> 568 | E11: =D11*1000000 -> 568000000 | F11: =FV($L$1,$L$2,,-E11,1) -> 6.9341113e+08 | G11: =PMT($L$3,$L$2,,-F11,1) -> 10631656 | H11: {=SUM(G11*(1+$L$3)^ROW(INDIRECT("1:"&$L$2)))} -> 6.9341113e+08 | I11: =G11/B11 -> 15275.368 | J11: =I11/($T$2*$R$2) -> 1.937515
A12: JEK2* | B12: =1250 -> 1250 | C12: 3227 (2024) | D12: =3227*$C$69 -> 2185.4139 | E12: =D12*1000000 -> 2.1854139e+09 | F12: =FV($R$3,$L$2,,-E12,1) -> 2.1854139e+09 | G12: =PMT($R$4,$L$2,,-F12,1) -> 39675708 | H12: {=SUM(G12*(1+$R$4)^ROW(INDIRECT("1:"&$L$2)))} -> 2.1854139e+09 | I12: =G12/B12 -> 31740.566 | J12: =I12/($T$2*$Q$2) -> 3.8960778
A13: JEK2* | B13: =1250 -> 1250 | C13: 3227 (2024) | D13: =3227*$C$69 -> 2185.4139 | E13: =D13*1000000 -> 2.1854139e+09 | F13: =FV($R$3,$L$2,,-E13,1) -> 2.1854139e+09 | G13: =PMT($R$4,$L$2,,-F13,1) -> 39675708 | H13: {=SUM(G13*(1+$R$4)^ROW(INDIRECT("1:"&$L$2)))} -> 2.1854139e+09 | I13: =G13/B13 -> 31740.566 | J13: =I13/($T$2*$Q$2) -> 3.8960778
A14: Čehi | I14: =$D$81 -> 45454.918 | J14: =I14/($T$2*$S$2) -> 5.7441892 | K14: Leta | L14: 60
A15: 60 LET
A16: =A2 -> Jedrska elektrarna | B16: =B2 -> Moč reaktorja (MW) | C16: =C2 -> Cena razgradnje 2020-2023 (mio. €) | D16: =D2 -> Cena razgradnje 2024 (mio. €) | E16: =E2 -> Cena razgradnje 2024 [EUR] | F16: Cena razgradnje povečana za escalation rate (y + 60) | G16: Letno plačilo, da v 60 letih pridemo do končne investicijske vrednosti | H16: Preverba, da prideš do istih cifer | I16: Strošek (€/MW/leto) | J16: Strošek (€/MWh)
A17: =A3 -> Fessenheim 1,2 (Francija) | B17: =B3 -> 1840 | C17: =C3 -> 808 (2021) | D17: =D3 -> 910.616 | E17: =E3 -> 910616000 | F17: =FV($L$1,$L$14,,-E17,1) -> 1.2282845e+09 | G17: =PMT($L$3,$L$14,,-F17,1) -> 9652487.5 | H17: {=SUM(G17*(1+$L$3)^ROW(INDIRECT("1:"&$L$14)))} -> 1.2282845e+09 | I17: =G17/B17 -> 5245.9171 | J17: =I17/($T$2*$S$2) -> 0.66293246
A18: =A4 -> Chooz-A (Francija) | B18: =B4 -> 320 | C18: =C4 -> 280 (2021) | D18: =D4 -> 315.56 | E18: =E4 -> 315560000 | F18: =FV($L$1,$L$14,,-E18,1) -> 4.2564315e+08 | G18: =PMT($L$3,$L$14,,-F18,1) -> 3344921.4 | H18: {=SUM(G18*(1+$L$3)^ROW(INDIRECT("1:"&$L$14)))} -> 4.2564315e+08 | I18: =G18/B18 -> 10452.879 | J18: =I18/($T$2*$S$2) -> 1.3209421
A19: =A5 -> Super-Phenix (Francija) | B19: =B5 -> 1242 | C19: =C5 -> 520.5 (2021) | D19: =D5 -> 586.6035 | E19: =E5 -> 586603500 | F19: =FV($L$1,$L$14,,-E19,1) -> 7.9124022e+08 | G19: =PMT($L$3,$L$14,,-F19,1) -> 6217970 | H19: {=SUM(G19*(1+$L$3)^ROW(INDIRECT("1:"&$L$14)))} -> 7.9124022e+08 | I19: =G19/B19 -> 5006.417 | J19: =I19/($T$2*$S$2) -> 0.63266656 | K19: Strošek (€/MW/leto) | M19: Strošek (€/MWh)
A20: =A6 -> Obrigheim (Nemčija) | B20: =B6 -> 340 | C20: =C6 -> 630.4 (2020) | D20: =D6 -> 844.736 | E20: =E6 -> 844736000 | F20: =FV($L$1,$L$14,,-E20,1) -> 1.1394223e+09 | G20: =PMT($L$3,$L$14,,-F20,1) -> 8954162.5 | H20: {=SUM(G20*(1+$L$3)^ROW(INDIRECT("1:"&$L$14)))} -> 1.1394223e+09 | I20: =G20/B20 -> 26335.772 | J20: =I20/($T$2*$S$2) -> 3.3280812 | K20: Min | L20: =MIN(I17:I28) -> 5006.417 | M20: Min | N20: =MIN(J17:J28) -> 0.63266656
A21: =A7 -> Muelheim-Kaerlich (Nemčija) | B21: =B7 -> 1219 | C21: =C7 -> 761.7 (2020) | D21: =D7 -> 1020.678 | E21: =E7 -> 1.020678e+09 | F21: =FV($L$1,$L$14,,-E21,1) -> 1.3767417e+09 | G21: =PMT($L$3,$L$14,,-F21,1) -> 10819140 | H21: {=SUM(G21*(1+$L$3)^ROW(INDIRECT("1:"&$L$14)))} -> 1.3767417e+09 | I21: =G21/B21 -> 8875.4221 | J21: =I21/($T$2*$S$2) -> 1.1215971 | K21: Average | L21: =AVERAGE(I17:I28) -> 15365.654 | M21: Average | N21: =AVERAGE(J17:J28) -> 1.9313006
A22: =A8 -> Greifswald 1-5 (Nemčija) | B22: =B8 -> 2040 | C22: =C8 -> 4202.4 (2020) | D22: =D8 -> 5631.216 | E22: =E8 -> 5.631216e+09 | F22: =FV($L$1,$L$14,,-E22,1) -> 7.5956666e+09 | G22: =PMT($L$3,$L$14,,-F22,1) -> 59690629 | H22: {=SUM(G22*(1+$L$3)^ROW(INDIRECT("1:"&$L$14)))} -> 7.5956666e+09 | I22: =G22/B22 -> 29260.112 | J22: =I22/($T$2*$S$2) -> 3.6976334 | K22: Max | L22: =MAX(I17:I28) -> 29260.112 | M22: Max | N22: =MAX(J17:J28) -> 3.6976334
A23: =A9 -> Beznau 1, 2 (Švica) | B23: =B9 -> 730 | C23: =C9 -> 887,5 (2020) | D23: =D9 -> 1189.25 | E23: =E9 -> 1189250000 | F23: =FV($L$1,$L$14,,-E23,1) -> 1.60412e+09 | G23: =PMT($L$3,$L$14,,-F23,1) -> 12605995 | H23: {=SUM(G23*(1+$L$3)^ROW(INDIRECT("1:"&$L$14)))} -> 1.60412e+09 | I23: =G23/B23 -> 17268.486 | J23: =I23/($T$2*$S$2) -> 2.1822381 | K23: Min distribucije | L23: =$L$20 -> 5006.417 | M23: Min distribucije | N23: =$N$20 -> 0.63266656
A24: =A10 -> Gosgen (Švica) | B24: =B10 -> 1010 | C24: =C10 -> 835.2 (2020) | D24: =D10 -> 1119.168 | E24: =E10 -> 1.119168e+09 | F24: =FV($L$1,$L$14,,-E24,1) -> 1.5095899e+09 | G24: =PMT($L$3,$L$14,,-F24,1) -> 11863129 | H24: {=SUM(G24*(1+$L$3)^ROW(INDIRECT("1:"&$L$14)))} -> 1.5095899e+09 | I24: =G24/B24 -> 11745.672 | J24: =I24/($T$2*$S$2) -> 1.4843138 | K24: Max distribucije | L24: =$L$22 -> 29260.112 | M24: Max distribucije | N24: =$N$22 -> 3.6976334
A25: JEK1 | B25: 696 | C25: =C11 -> 568 (2024) | D25: =D11 -> 568 | E25: =D25*1000000 -> 568000000 | F25: =FV($L$1,$L$14,,-E25,1) -> 7.6614689e+08 | G25: =PMT($L$3,$L$14,,-F25,1) -> 6020773.7 | H25: {=SUM(G25*(1+$L$3)^ROW(INDIRECT("1:"&$L$14)))} -> 7.6614689e+08 | I25: =G25/B25 -> 8650.537 | J25: =I25/($T$2*$R$2) -> 1.0972269
A26: JEK2* | B26: =1250 -> 1250 | C26: 3227 (2024) | D26: =3227*$C$69 -> 2185.4139 | E26: =D26*1000000 -> 2.1854139e+09 | F26: =FV($R$3,$L$14,,-E26,1) -> 2.1854139e+09 | G26: =PMT($R$4,$L$14,,-F26,1) -> 22378266 | H26: {=SUM(G26*(1+$R$4)^ROW(INDIRECT("1:"&$L$14)))} -> 2.1854139e+09 | I26: =G26/B26 -> 17902.613 | J26: =I26/($T$2*$Q$2) -> 2.1975025
A27: JEK2* | B27: =1250 -> 1250 | C27: 3227 (2024) | D27: =3227*$C$69 -> 2185.4139 | E27: =D27*1000000 -> 2.1854139e+09 | F27: =FV($R$3,$L$14,,-E27,1) -> 2.1854139e+09 | G27: =PMT($R$4,$L$14,,-F27,1) -> 22378266 | H27: {=SUM(G27*(1+$R$4)^ROW(INDIRECT("1:"&$L$14)))} -> 2.1854139e+09 | I27: =G27/B27 -> 17902.613 | J27: =I27/($T$2*$Q$2) -> 2.1975025
A28: =$A$14 -> Čehi | I28: =$C$81 -> 25741.406 | J28: =I28/($T$2*$S$2) -> 3.2529705 | K28: Leta | L28: 80
A29: 80 LET
A30: =A16 -> Jedrska elektrarna | B30: =B16 -> Moč reaktorja (MW) | C30: =C16 -> Cena razgradnje 2020-2023 (mio. €) | D30: =D16 -> Cena razgradnje 2024 (mio. €) | E30: =E16 -> Cena razgradnje 2024 [EUR] | F30: Cena razgradnje povečana za escalation rate (y + 80) | G30: Letno plačilo, da v 80 letih pridemo do končne investicijske vrednosti | H30: Preverba, da prideš do istih cifer | I30: Strošek (€/MW/leto) | J30: Strošek (€/MWh)
A31: =A17 -> Fessenheim 1,2 (Francija) | B31: =B17 -> 1840 | C31: =C17 -> 808 (2021) | D31: =D17 -> 910.616 | E31: =E17 -> 910616000 | F31: =FV($L$1,$L$28,,-E31,1) -> 1.3571261e+09 | G31: =PMT($L$3,$L$28,,-F31,1) -> 6057308.6 | H31: {=SUM(G31*(1+$L$3)^ROW(INDIRECT("1:"&$L$28)))} -> 1.3571261e+09 | I31: =G31/B31 -> 3292.0155 | J31: =I31/($T$2*$S$2) -> 0.41601571
A32: =A18 -> Chooz-A (Francija) | B32: =B18 -> 320 | C32: =C18 -> 280 (2021) | D32: =D18 -> 315.56 | E32: =E18 -> 315560000 | F32: =FV($L$1,$L$28,,-E32,1) -> 4.7029124e+08 | G32: =PMT($L$3,$L$28,,-F32,1) -> 2099067.3 | H32: {=SUM(G32*(1+$L$3)^ROW(INDIRECT("1:"&$L$28)))} -> 4.7029124e+08 | I32: =G32/B32 -> 6559.5854 | J32: =I32/($T$2*$S$2) -> 0.8289422 | K32: Strošek (€/MW/leto) | M32: Strošek (€/MWh)
A33: =A19 -> Super-Phenix (Francija) | B33: =B19 -> 1242 | C33: =C19 -> 520.5 (2021) | D33: =D19 -> 586.6035 | E33: =E19 -> 586603500 | F33: =FV($L$1,$L$28,,-E33,1) -> 8.7423782e+08 | G33: =PMT($L$3,$L$28,,-F33,1) -> 3902016.2 | H33: {=SUM(G33*(1+$L$3)^ROW(INDIRECT("1:"&$L$28)))} -> 8.7423782e+08 | I33: =G33/B33 -> 3141.72 | J33: =I33/($T$2*$S$2) -> 0.3970227 | K33: Min | L33: =MIN(I31:I42) -> 3141.72 | M33: Min | N33: =MIN(J31:J42) -> 0.3970227
A34: =A20 -> Obrigheim (Nemčija) | B34: =B20 -> 340 | C34: =C20 -> 630.4 (2020) | D34: =D20 -> 844.736 | E34: =E20 -> 844736000 | F34: =FV($L$1,$L$28,,-E34,1) -> 1.2589426e+09 | G34: =PMT($L$3,$L$28,,-F34,1) -> 5619082.7 | H34: {=SUM(G34*(1+$L$3)^ROW(INDIRECT("1:"&$L$28)))} -> 1.2589426e+09 | I34: =G34/B34 -> 16526.714 | J34: =I34/($T$2*$S$2) -> 2.0884995 | K34: Average | L34: =AVERAGE(I31:I42) -> 9650.0186 | M34: Average | N34: =AVERAGE(J31:J42) -> 1.207872
A35: =A21 -> Muelheim-Kaerlich (Nemčija) | B35: =B21 -> 1219 | C35: =C21 -> 761.7 (2020) | D35: =D21 -> 1020.678 | E35: =E21 -> 1.020678e+09 | F35: =FV($L$1,$L$28,,-E35,1) -> 1.5211558e+09 | G35: =PMT($L$3,$L$28,,-F35,1) -> 6789427.8 | H35: {=SUM(G35*(1+$L$3)^ROW(INDIRECT("1:"&$L$28)))} -> 1.5211558e+09 | I35: =G35/B35 -> 5569.6701 | J35: =I35/($T$2*$S$2) -> 0.70384549 | K35: Max | L35: =MAX(I31:I42) -> 18361.85 | M35: Max | N35: =MAX(J31:J42) -> 2.3204077
A36: =A22 -> Greifswald 1-5 (Nemčija) | B36: =B22 -> 2040 | C36: =C22 -> 4202.4 (2020) | D36: =D22 -> 5631.216 | E36: =E22 -> 5.631216e+09 | F36: =FV($L$1,$L$28,,-E36,1) -> 8.3924184e+09 | G36: =PMT($L$3,$L$28,,-F36,1) -> 37458175 | H36: {=SUM(G36*(1+$L$3)^ROW(INDIRECT("1:"&$L$28)))} -> 8.3924184e+09 | I36: =G36/B36 -> 18361.85 | J36: =I36/($T$2*$S$2) -> 2.3204077 | K36: Min distribucije | L36: =$L$33 -> 3141.72 | M36: Min distribucije | N36: =$N$33 -> 0.3970227
A37: =A23 -> Beznau 1, 2 (Švica) | B37: =B23 -> 730 | C37: =C23 -> 887,5 (2020) | D37: =D23 -> 1189.25 | E37: =E23 -> 1189250000 | F37: =FV($L$1,$L$28,,-E37,1) -> 1.7723851e+09 | G37: =PMT($L$3,$L$28,,-F37,1) -> 7910748.6 | H37: {=SUM(G37*(1+$L$3)^ROW(INDIRECT("1:"&$L$28)))} -> 1.7723851e+09 | I37: =G37/B37 -> 10836.642 | J37: =I37/($T$2*$S$2) -> 1.3694387 | K37: Max distribucije | L37: =$L$35 -> 18361.85 | M37: Max distribucije | N37: =$N$35 -> 2.3204077
A38: =A24 -> Gosgen (Švica) | B38: =B24 -> 1010 | C38: =C24 -> 835.2 (2020) | D38: =D24 -> 1119.168 | E38: =E24 -> 1.119168e+09 | F38: =FV($L$1,$L$28,,-E38,1) -> 1.6679392e+09 | G38: =PMT($L$3,$L$28,,-F38,1) -> 7444571.5 | H38: {=SUM(G38*(1+$L$3)^ROW(INDIRECT("1:"&$L$28)))} -> 1.6679392e+09 | I38: =G38/B38 -> 7370.8629 | J38: =I38/($T$2*$S$2) -> 0.93146425
A39: JEK1 | B39: 696 | C39: =C11 -> 568 (2024) | D39: =D11 -> 568 | E39: =D39*1000000 -> 568000000 | F39: =FV($L$1,$L$28,,-E39,1) -> 8.4651231e+08 | G39: =PMT($L$3,$L$28,,-F39,1) -> 3778268 | H39: {=SUM(G39*(1+$L$3)^ROW(INDIRECT("1:"&$L$28)))} -> 8.4651231e+08 | I39: =G39/B39 -> 5428.546 | J39: =I39/($T$2*$R$2) -> 0.68855225
A40: JEK2* | B40: =1250 -> 1250 | C40: 3227 (2024) | D40: =3227*$C$69 -> 2185.4139 | E40: =D40*1000000 -> 2.1854139e+09 | F40: =FV($R$3,$L$28,,-E40,1) -> 2.1854139e+09 | G40: =PMT($R$4,$L$28,,-F40,1) -> 14099306 | H40: {=SUM(G40*(1+$R$4)^ROW(INDIRECT("1:"&$L$28)))} -> 2.1854139e+09 | I40: =G40/B40 -> 11279.445 | J40: =2*$C$69 -> 1.3544554
...

Sheet Nadomestilo občini in voda
A1: Nadomestilo za omejeno rabo prostora in vodno povračilo [EUR/leto od začetka gradnje]
A2: 1000 MW | B2: =9953000 -> 9953000 | C2: 10441000
A3: 1250 MW | B3: =12910000 -> 12910000 | C3: 13562000
A4: 1650 MW | B4: =17641000 -> 17641000 | C4: 18556000

Sheet NPP accident insurance premium
A1: Zavarovalna premija za primer jedrske nesreče [EUR/MWh] | B1: 0 | C1: VKLJUČEVA V OPEX-U, ZATO TUKAJ 0

Sheet Tveganja
A1: Verjetnost za politično zaprtje v času gradnje JE [%] | B1: 0.005
A2: Verjetnost za politično zaprtje v času obratovanja JE [%] | B2: 0.02
A3: Verjetnost za zaprtje JE zaradi tehnične napake [%] | B3: 0.017

Sheet Ostale postavke
A1: Davek od dohodkov pravnih oseb (DDPO) | B1: 0.19

Sheet Cena elektrike
A1: Normalna porazdelitev - tuja (desno) in GEN Energija študija | B1: Pogostnost pojavljanja [%] | C1: Mean | D1: Standardna deviacija
A2: Scenarij nizka cena | B2: 0.2 | C2: 59.5 | D2: =$B$5*C2 -> 7.5084553
A3: Scenarij srednja cena | B3: 0.6 | C3: 68 | D3: =$B$5*C3 -> 8.5810918
A4: Scenarij visoka cena | B4: 0.2 | C4: 96.5 | D4: =$B$5*C4 -> 12.177579 | E4: Cene vzete iz grafa ob pomoči ekstrakcije podatkov iz grafa
A5: Standardna deviacija stran od srednje vrednosti [% od srednje vrednosti] | B5: 0.12619253 | D5: =C4+3*D4 -> 133.03274
A6: Real escalation rate [%] | B6: 0
A7: Zbrali nemške mesečne futurse, ki so 120 EUR/MWh ali višji, saj je 2SD od scenarija z visoko ceno 121 EUR/MWh meja | C7: študija
A8: Možnost, da se zgodi izjemen skok v cenah [%] | B8: =1/15 -> 0.066666667 | C8: prilagojena vrednost iz eurostata
A9: Triangularna porazdelitev
A10: Višina realnih cen, če do skoka pride - min [EUR/MWh] | B10: 133.05623
A11: Višina realnih cen, če do skoka pride - mean [EUR/MWh] | B11: 233.4634
A12: Višina realnih cen, če do skoka pride - max [EUR/MWh] | B12: 465.18

Sheet Potrdila o izvoru
A1: Potrdilo o izvoru - prihodek [EUR/MWh] | B1: 1
